Workbook

Sheet Agendamento
A1: Nome Fornecedor | B1: Título | C1: Acervo | D1: Rua | E1: Quantidade | F1: Qtde de Posições Paletes | G1: Peso Presumido (kg) | H1: Data pedido de agendamento (Quando chegou o e-mail) | I1: Data prevista para recebimento (Data de agendamento) | J1: Data Recebimento (Chegada do veículo em Cajamar) | K1: Hora do recebimento | L1: Tipo de Veículo (3 ton, 7 ton, etc) | M1: Placa Veículo | N1: Peso Total Recebido | O1: Status
A2: COMBOIO DE CORDA EDITORA LTDA-não há | B2: UM SONHO FEITO DE LINHAS | C2: #NAME? | D2: #NAME? | E2: 34858 | F2: 5 | G2: 4078 | H2: 46042 | I2: 46045 | J2: 46045 | K2: 0.375 | O2: RECEBIDO
A3: EDITORA ANZOL LTDA-não há | B3: SILÊNCIO! | C3: #NAME? | D3: #NAME? | E3: 30241 | F3: 7 | G3: 5171 | H3: 46042 | I3: 46045 | J3: 46045 | K3: 0.375 | L3: 19t | O3: RECEBIDO
A4: COMBOIO DE CORDA EDITORA LTDA-não há | B4: REFÚGIO | C4: #NAME? | D4: #NAME? | E4: 32777 | F4: 6 | G4: 3835 | H4: 46042 | I4: 46045 | J4: 46045 | K4: 0.375 | L4: 19t | O4: RECEBIDO
A5: EDITORA ANZOL LTDA-não há | B5: ADIVINHA-ME! | C5: #NAME? | D5: #NAME? | E5: 46437 | F5: 6 | G5: 5433 | H5: 46042 | I5: 46045 | J5: 46045 | K5: 0.375 | O5: RECEBIDO
A6: EDITORA MOITARÁ LTDA-não há | B6: PLANTANDO AS ÁRVORES DO QUÊNIA: A HISTÓRIA DE WANGARI MAATHAI | C6: #NAME? | D6: #NAME? | E6: 26425 | F6: 4 | G6: 3092 | H6: 46042 | I6: 46048 | J6: 46048 | K6: 0.375 | L6: 19t | O6: RECEBIDO
A7: EDITORA MOITARÁ LTDA-não há | B7: DAGMAR E LEONOR | C7: #NAME? | D7: #NAME? | E7: 33101 | F7: 6 | G7: 4469 | H7: 46042 | I7: 46048 | J7: 46048 | K7: 0.375 | L7: 19t | O7: RECEBIDO
A8: EDITORA RODOPIO LTDA-não há | B8: UM PASSEIO NA FLORESTA AMAZÔNICA | C8: #NAME? | D8: #NAME? | E8: 63912 | F8: 8 | G8: 9779 | H8: 46042 | I8: 46048 | J8: 46048 | K8: 0.39583333 | L8: 19t | O8: RECEBIDO
A9: EDITORA RODOPIO LTDA-não há | B9: A VACA PRESEPEIRA | C9: #NAME? | D9: #NAME? | E9: 103512 | F9: 10 | G9: 6832 | H9: 46042 | I9: 46048 | J9: 46048 | K9: 0.39583333 | L9: 19t | O9: RECEBIDO
A10: PETRA EDITORIAL LTDA -Não há | B10: SONHANDO SANTOS DUMONT | C10: #NAME? | D10: #NAME? | E10: 38892 | F10: 3 | G10: 3734 | H10: 46045 | I10: 46048 | J10: 46048 | K10: 0.41666667 | L10: 14t | O10: RECEBIDO
A11: PETRA EDITORIAL LTDA -Não há | B11: O ROUXINOL E OUTRAS HISTÓRIAS | C11: #NAME? | D11: #NAME? | E11: 23722 | F11: 5 | G11: 3867 | H11: 46045 | I11: 46048 | J11: 46048 | K11: 0.41666667 | L11: 19t | O11: RECEBIDO
A12: EDITORA MAMUTE LTDA-não há | B12: O PEQUENO PRÍNCIPE PRETO | C12: #NAME? | D12: #NAME? | E12: 63210 | F12: 7 | G12: 6068 | H12: 46045 | I12: 46048 | J12: 46048 | K12: 0.41666667 | L12: 19t | O12: RECEBIDO
A13: PRESTIGIO EDITORIAL LTDA-PRESTIGIO EDITORIAL LTDA | B13: O GATO SEM BOTAS | C13: #NAME? | D13: #NAME? | E13: 27515 | F13: 3 | G13: 2174 | H13: 46045 | I13: 46048 | J13: 46048 | K13: 0.41666667 | L13: 14t | O13: RECEBIDO
A14: PRESTIGIO EDITORIAL LTDA-PRESTIGIO EDITORIAL LTDA | B14: O AZULÃO E O SOL | C14: #NAME? | D14: #NAME? | E14: 38929 | F14: 4 | G14: 3075 | H14: 46045 | I14: 46048 | J14: 46048 | K14: 0.41666667 | L14: 19t | M14: CPR-6636/GVK-7142 | O14: RECEBIDO
A15: TRAMA EDITORA LTDA-Não há | B15: FULUSTRECA | C15: #NAME? | D15: #NAME? | E15: 38581 | F15: 4 | G15: 3704 | H15: 46045 | I15: 46048 | J15: 46048 | K15: 0.41666667 | L15: 19t | O15: RECEBIDO
A16: TRAMA EDITORA LTDA-Não há | B16: CANTIGAMENTE | C16: #NAME? | D16: #NAME? | E16: 23707 | F16: 4 | G16: 2276 | H16: 46045 | I16: 46048 | J16: 46048 | K16: 0.41666667 | L16: 19t | O16: RECEBIDO
A17: EDIÇÕES SM LTDA-SM EDUCAÇÃO | B17: O FABULOSO PROFESSOR FRITZ E A MENINA DAS PÉTALAS AMARELAS | C17: #NAME? | D17: #NAME? | E17: 102566 | F17: 13 | G17: 10359 | H17: 46042 | I17: 46049 | J17: 46049 | K17: 0.375 | L17: 14t | M17: CYR7I02 - GDR8A77 | N17: 10359.166 | O17: RECEBIDO
A18: EDIÇÕES SM LTDA-SM EDUCAÇÃO | B18: ALICE NO TELHADO | C18: #NAME? | D18: #NAME? | E18: 33601 | F18: 5 | G18: 3931 | H18: 46042 | I18: 46049 | J18: 46049 | K18: 0.375 | L18: 19t | M18: CYR7I02 - GDR8A77 | N18: 3931.317 | O18: RECEBIDO
A19: EDITORA TIMBÓ LTDA-não há | B19: FELICIDADE É UMA PALAVRA SIMPLES | C19: #NAME? | D19: #NAME? | E19: 44353 | F19: 5 | G19: 4391 | H19: 46042 | I19: 46049 | J19: 46049 | K19: 0.39583333 | L19: 14t | M19: CYR7I02 - GDR8A77 | N19: 4390.947 | O19: RECEBIDO
A20: EDITORA TIMBÓ LTDA-não há | B20: FABULOSOS E ASSUSTADORES! CRIATURAS E BICHOS DO FOLCLORE BRASILEIRO | C20: #NAME? | D20: #NAME? | E20: 46765 | F20: 8 | G20: 6313 | H20: 46042 | I20: 46049 | J20: 46049 | K20: 0.39583333 | L20: 14t | M20: CYR7I02 - GDR8A77 | N20: 6313.275 | O20: RECEBIDO
A21: PALAVRAS PROJETOS EDITORIAIS LTDA-PALAVRAS | B21: SOU DE VERDADE | C21: #NAME? | D21: #NAME? | E21: 37023 | F21: 6 | G21: 3554 | H21: 46042 | I21: 46049 | J21: 46049 | K21: 0.41666667 | L21: 14t | M21: PWG-2228 | N21: 4980.7 | O21: RECEBIDO
A22: PALAVRAS PROJETOS EDITORIAIS LTDA-PALAVRAS | B22: SEM-NO E JORGE | C22: #NAME? | D22: #NAME? | E22: 24255 | F22: 3 | G22: 1916 | H22: 46042 | I22: 46049 | J22: 46049 | K22: 0.41666667 | L22: 14t | M22: GJK3J03 | N22: 2232 | O22: RECEBIDO
A23: PALAVRINHAS PROJETOS EDITORIAIS LTDA-PALAVRINHAS | B23: PARA ONDE ME LEVAM OS MEUS PÉS? | C23: #NAME? | D23: #NAME? | E23: 48043 | F23: 7 | G23: 4612 | H23: 46042 | I23: 46049 | J23: 46049 | K23: 0.41666667 | L23: 14t | M23: PWG-2228 | N23: 6245.59 | O23: RECEBIDO
A24: PALAVRINHAS PROJETOS EDITORIAIS LTDA-PALAVRINHAS | B24: O RECICLADOR DE PALAVRAS | C24: #NAME? | D24: #NAME? | E24: 31228 | F24: 3 | G24: 1468 | H24: 46042 | I24: 46049 | J24: 46049 | K24: 0.41666667 | L24: 14t | M24: GJK3J03 | N24: 2029.82 | O24: RECEBIDO
A25: Enquete Editora e Comunicação LTDA-Potencial Editora | B25: ABC DAS EMOÇÕES | C25: #NAME? | D25: #NAME? | E25: 86938 | F25: 15 | G25: 7998 | H25: 46045 | I25: 46049 | J25: 46049 | K25: 0.4375 | L25: 14t | M25: DRL3935 | N25: 7303 | O25: RECEBIDO
A26: Enquete Editora e Comunicação LTDA-Potencial Editora | B26: A MENINA E A HARPIA: LENDAS BRASILEIRAS | C26: #NAME? | D26: #NAME? | E26: 37781 | F26: 15 | G26: 6801 | H26: 46045 | I26: 46049 | J26: 46049 | K26: 0.4375 | L26: 14t | M26: DRL3935 | N26: 6726.798 | O26: RECEBIDO
A27: EDITORA GRAFSET LTDA-EDITORA GRAFSET | B27: TRÊS SEMENTES DIFERENTES | C27: #NAME? | D27: #NAME? | E27: 29030 | F27: 5 | G27: 2961 | H27: 46045 | I27: 46049 | J27: 46049 | K27: 0.45833333 | L27: 14t | M27: AUF9A02 | N27: 677.425 | O27: RECEBIDO
A28: LUNIK SOLUCOES EDUCACIONAIS EIRELI-LUNIK EDUCACAO | B28: SOFIA | C28: #NAME? | D28: #NAME? | E28: 27065 | F28: 4 | G28: 2761 | H28: 46045 | I28: 46049 | J28: 46049 | K28: 0.45833333 | L28: 14t | M28: AUF9A02 | N28: 681.125 | O28: RECEBIDO
... A30: MVC EDITORA LTDA-MVC EDITORA | B30: BICHO QUE VAI, GENTE QUE VEM | C30: #NAME? | D30: #NAME? | E30: 37674 | F30: 6 | G30: 3843 | H30: 46045 | I30: 46049 | J30: 46049 | K30: 0.47916667 | L30: 14t | M30: AUF9A02 | N30: 683.075 | O30: RECEBIDO
A31: ESTANTE DE LIVROS EDITORA LTDA-Não há | B31: SOU UM RIO | C31: #NAME? | D31: #NAME? | E31: 34549 | F31: 4 | G31: 3593 | H31: 46048 | I31: 46050 | J31: 46050 | K31: 0.375 | L31: 14t | N31: 3393 | O31: RECEBIDO
A32: EDITORA ONCA-PINTADA LTDA-não há | B32: O PREFEITO PERFEITO | C32: #NAME? | D32: #NAME? | E32: 34964 | F32: 4 | G32: 3357 | H32: 46048 | I32: 46050 | J32: 46050 | K32: 0.375 | L32: 14t | N32: 3356 | O32: RECEBIDO
A33: EDITORA ONCA-PINTADA LTDA-não há | B33: GERTRUDES TRUDES TUTUDES | C33: #NAME? | D33: #NAME? | E33: 27080 | F33: 3 | G33: 2139 | H33: 46048 | I33: 46050 | J33: 46050 | K33: 0.375 | L33: 14t | N33: 2139 | O33: RECEBIDO
A34: ESTANTE DE LIVROS EDITORA LTDA-Não há | B34: A CANOA QUE VIROU COISA | C34: #NAME? | D34: #NAME? | E34: 43187 | F34: 4 | G34: 3412 | H34: 46048 | I34: 46050 | J34: 46050 | K34: 0.375 | L34: 14t | N34: 3411 | O34: RECEBIDO
A35: EDITORA ENSINO E CONHECIMENTO LTDA-ENSINO E CONHECIMENTO | B35: O PLANETA DISTANTE | C35: #NAME? | D35: #NAME? | E35: 44922 | F35: 5 | G35: 4717 | H35: 46048 | I35: 46050 | J35: 46050 | K35: 0.39583333 | L35: 14t | N35: 4716 | O35: RECEBIDO
A36: EDITORA ENSINO E CONHECIMENTO LTDA-ENSINO E CONHECIMENTO | B36: O HERÓI IMÓVEL | C36: #NAME? | D36: #NAME? | E36: 29115 | F36: 4 | G36: 3057 | H36: 46048 | I36: 46050 | J36: 46050 | K36: 0.39583333 | L36: 14t | N36: 2854 | O36: RECEBIDO
A37: VITRINE EDITORA LTDA-Não há | B37: ÁGUA, GAIA, FOGO E AR | C37: #NAME? | D37: #NAME? | E37: 37358 | F37: 4 | G37: 3586 | H37: 46048 | I37: 46050 | J37: 46050 | K37: 0.39583333 | L37: 14t | N37: 3586 | O37: RECEBIDO
A38: VITRINE EDITORA LTDA-Não há | B38: A OBRA | C38: #NAME? | D38: #NAME? | E38: 46215 | F38: 6 | G38: 4437 | H38: 46048 | I38: 46050 | J38: 46050 | K38: 0.39583333 | L38: 14t | N38: 4613.07 | O38: RECEBIDO
A39: Zapt Editora Ltda.-Zapt Editora | B39: VIU? | C39: #NAME? | D39: #NAME? | E39: 33264 | F39: 5 | G39: 2362 | H39: 46048 | I39: 46050 | J39: 46050 | K39: 0.41666667 | L39: 14t | M39: CUO1A15 | N39: 3539 | O39: RECEBIDO
A40: ARCO 43 EDITORA LTDA-ARCO 43 | B40: O ENCONTRO DA CIDADE CRIANÇA COM O SERTÃO MENINO | C40: #NAME? | D40: #NAME? | E40: 58821 | F40: 7 | G40: 5647 | H40: 46048 | I40: 46050 | J40: 46050 | K40: 0.4375 | L40: 14t | M40: DAS7E24 | N40: 5778 | O40: RECEBIDO
A41: EDITORA DO BRASIL S/A-EDITORA DO BRASIL | B41: VÁRIAS MANEIRAS DE AMAR | C41: #NAME? | D41: #NAME? | E41: 44982 | F41: 7 | G41: 5083 | H41: 46048 | I41: 46050 | J41: 46050 | K41: 0.45833333 | L41: 14t | M41: DAS7E24 | N41: 5435 | O41: RECEBIDO
...

Sheet Obras e Acervos
A1: CHAVE | B1: CHAVE | C1: CNPJ | D1: editora | E1: categoria | F1: titulo_colecao | G1: código_volume | H1: Código IMPRESSÃO | I1: ISBN | J1: formato | K1: exemplar | L1: serie | M1: título_volume | N1: paginas | O1: peso_g | P1: peso_kg | Q1: Formato Editora | R1: Gramatura miolo | S1: Acervo | T1: tiragem | U1: peso_tiragem | V1: valor unitário | W1: valor total | X1: Data Recebimento | Y1: LINK NF
A2: =CONCATENATE(LEFT(C2,12),"-",RIGHT(C2,2),"_",TEXT(X2,"ddmmaaaa"),"_",COUNTIF($C$2:C2,C2)) -> 249063420001-33_26022026_1 | B2: =CONCATENATE(LEFT(C2,12),"-",RIGHT(C2,2),"_",COUNTIF($C$2:C2,C2)) -> 249063420001-33_1 | C2: 24906342000133 | D2: IBEP SISTEMAS DE ENSINO-IBEP SISTEMAS | E2: CATEGORIA 1: OBRAS LIT. DO 1º AO 3º ANO | F2: GRÃO DE AFETO | G2: IMLE0000300799P230301000000 | H2: 0799L23000030LE | I2: 9786589831051 | J2: Impresso | K2: Livro do estudante | L2: 1º ao 3º ano | M2: GRÃO DE AFETO | N2: 32 | O2: 93 | P2: 0.093 | Q2: 205x275 | R2: 80 | S2: 1 | T2: 72259 | U2: 6720.087 | V2: 4.2 | W2: 303487.8 | X2: =VLOOKUP($F2,Agendamento!$B:$J,9,0) -> 46079 | Y2: =COUNTIF(Analise!F:F,'Obras e Acervos'!H2) -> 1
A3: =CONCATENATE(LEFT(C3,12),"-",RIGHT(C3,2),"_",TEXT(X3,"ddmmaaaa"),"_",COUNTIF($C$2:C3,C3)) -> 330363230001-94_28012026_1 | B3: =CONCATENATE(LEFT(C3,12),"-",RIGHT(C3,2),"_",COUNTIF($C$2:C3,C3)) -> 330363230001-94_1 | C3: 33036323000194 | D3: AKPALÔ EDITORA LTDA-AKPALÔ | E3: CATEGORIA 1: OBRAS LIT. DO 1º AO 3º ANO | F3: DE BEM COM A VIDA | G3: IMLE0000300562P230301000000 | H3: 0562L23000030LE | I3: 9786559070893 | J3: Impresso | K3: Livro do estudante | L3: 1º ao 3º ano | M3: DE BEM COM A VIDA | N3: 32 | O3: 96 | P3: 0.096 | Q3: 205x275 | R3: 75 | S3: 1 | T3: 60776 | U3: 5834.496 | V3: 4.44 | W3: 269845.44 | X3: =VLOOKUP($F3,Agendamento!$B:$J,9,0) -> 46050 | Y3: =COUNTIF(Analise!F:F,'Obras e Acervos'!H3) -> 1
A4: =CONCATENATE(LEFT(C4,12),"-",RIGHT(C4,2),"_",TEXT(X4,"ddmmaaaa"),"_",COUNTIF($C$2:C4,C4)) -> 280395150001-14_02032026_1 | B4: =CONCATENATE(LEFT(C4,12),"-",RIGHT(C4,2),"_",COUNTIF($C$2:C4,C4)) -> 280395150001-14_1 | C4: 28039515000114 | D4: ANDORINHAS EDITORIAL LTDA- | E4: CATEGORIA 1: OBRAS LIT. DO 1º AO 3º ANO | F4: O RAPAZ QUE CASOU COM UMA SAPA | H4: 0742L23000030LE | I4: 9786589777113 | J4: Impresso | K4: Livro do estudante | L4: 1º ao 3º ano | M4: O RAPAZ QUE CASOU COM UMA SAPA | N4: 28 | O4: 96 | P4: 0.096 | Q4: 205x275 | R4: 80 | S4: 1 | T4: 50065 | U4: 4806.24 | V4: 4.27 | W4: 213777.55 | X4: =VLOOKUP($F4,Agendamento!$B:$J,9,0) -> 46083 | Y4: =COUNTIF(Analise!F:F,'Obras e Acervos'!H4) -> 1
A5: =CONCATENATE(LEFT(C5,12),"-",RIGHT(C5,2),"_",TEXT(X5,"ddmmaaaa"),"_",COUNTIF($C$2:C5,C5)) -> 421578060001-38_11032026_1 | B5: =CONCATENATE(LEFT(C5,12),"-",RIGHT(C5,2),"_",COUNTIF($C$2:C5,C5)) -> 421578060001-38_1 | C5: 42157806000138 | D5: ARACARI EDITORA E ASSESSORIA LTDA -ARACARI EDITORIAL | E5: CATEGORIA 1: OBRAS LIT. DO 1º AO 3º ANO | F5: PAPAGAIO PEPETELA | G5: IMLE0000300952P230301000000 | H5: 0952L23000030LE | I5: 9786589969099 | J5: Impresso | K5: Livro do estudante | L5: 1º ao 3º ano | M5: PAPAGAIO PEPETELA | N5: 44 | O5: 130 | P5: 0.13 | Q5: 205x275 | R5: 80 | S5: 1 | T5: 49338 | U5: 6413.94 | V5: 5.84 | W5: 288133.92 | X5: =VLOOKUP($F5,Agendamento!$B:$J,9,0) -> 46092 | Y5: =COUNTIF(Analise!F:F,'Obras e Acervos'!H5) -> 1
A6: =CONCATENATE(LEFT(C6,12),"-",RIGHT(C6,2),"_",TEXT(X6,"ddmmaaaa"),"_",COUNTIF($C$2:C6,C6)) -> 330363230001-94_30012026_2 | B6: =CONCATENATE(LEFT(C6,12),"-",RIGHT(C6,2),"_",COUNTIF($C$2:C6,C6)) -> 330363230001-94_2 | C6: 33036323000194 | D6: AKPALÔ EDITORA LTDA-AKPALÔ | E6: CATEGORIA 2: OBRAS LIT. DO 4º E 5º ANO | F6: TRÊS HISTÓRIAS DE ENCANTO | G6: IMLE0000200563P230302000000 | H6: 0563L23000020LE | I6: 9786559070862 | J6: Impresso | K6: Livro do estudante | L6: 4º e 5º ano | M6: TRÊS HISTÓRIAS DE ENCANTO | N6: 56 | O6: 147 | P6: 0.147 | Q6: 205x275 | R6: 75 | S6: 19 | T6: 25861 | U6: 3801.567 | V6: 4.45 | W6: 261753.45 | X6: =VLOOKUP($F6,Agendamento!$B:$J,9,0) -> 46052 | Y6: =COUNTIF(Analise!F:F,'Obras e Acervos'!H6) -> 1
A7: =CONCATENATE(LEFT(C7,12),"-",RIGHT(C7,2),"_",TEXT(X7,"ddmmaaaa"),"_",COUNTIF($C$2:C7,C7)) -> 114065460001-63_25022026_1 | B7: =CONCATENATE(LEFT(C7,12),"-",RIGHT(C7,2),"_",COUNTIF($C$2:C7,C7)) -> 114065460001-63_1 | C7: 11406546000163 | D7: BELLATRIX SERVICOS EM TECNOLOGIA LTDA- | E7: CATEGORIA 1: OBRAS LIT. DO 1º AO 3º ANO | F7: O ANIVERSÁRIO DO TILTAPES | G7: IMLE0000300755P230301000000 | H7: 0755L23000030LE | I7: 9786599402098 | J7: Impresso | K7: Livro do estudante | L7: 1º ao 3º ano | M7: O ANIVERSÁRIO DO TILTAPES | N7: 32 | O7: 105 | P7: 0.105 | Q7: 205x275 | R7: 80 | S7: 1 | T7: 49913 | U7: 5240.865 | V7: 4.72 | W7: 235589.36 | X7: =VLOOKUP($F7,Agendamento!$B:$J,9,0) -> 46078 | Y7: =COUNTIF(Analise!F:F,'Obras e Acervos'!H7) -> 1
A8: =CONCATENATE(LEFT(C8,12),"-",RIGHT(C8,2),"_",TEXT(X8,"ddmmaaaa"),"_",COUNTIF($C$2:C8,C8)) -> 410757770001-00_29012026_1 | B8: =CONCATENATE(LEFT(C8,12),"-",RIGHT(C8,2),"_",COUNTIF($C$2:C8,C8)) -> 410757770001-00_1 | C8: 41075777000100 | D8: BENNU EDITORA E PROJETOS EDUCACIONAIS LTDA-BENNU EDITORA | E8: CATEGORIA 1: OBRAS LIT. DO 1º AO 3º ANO | F8: FÁBULAS DE ESOPO | G8: IMLE0000300683P230301000000 | H8: 0683L23000030LE | I8: 9786599552236 | J8: Impresso | K8: Livro do estudante | L8: 1º ao 3º ano | M8: FÁBULAS DE ESOPO - LIVRO DO ESTUDANTE | N8: 48 | O8: 115 | P8: 0.115 | Q8: 205x275 | R8: 80 | S8: 1 | T8: 76774 | U8: 8829.01 | V8: 5.56 | W8: 426863.44 | X8: =VLOOKUP($F8,Agendamento!$B:$J,9,0) -> 46051 | Y8: =COUNTIF(Analise!F:F,'Obras e Acervos'!H8) -> 1
A9: =CONCATENATE(LEFT(C9,12),"-",RIGHT(C9,2),"_",TEXT(X9,"ddmmaaaa"),"_",COUNTIF($C$2:C9,C9)) -> 040929430001-42_02032026_1 | B9: =CONCATENATE(LEFT(C9,12),"-",RIGHT(C9,2),"_",COUNTIF($C$2:C9,C9)) -> 040929430001-42_1 | C9: 04092943000142 | D9: BOM BINI EDITORA E ASSESSORIA LTDA-BAMBOOZINHO | E9: CATEGORIA 1: OBRAS LIT. DO 1º AO 3º ANO | F9: RABINHO, RABÃO, MACAQUINHO BRINCALHÃO | G9: IMLE0000300948P230301000000 | H9: 0948L23000030LE | I9: 9786589843030 | J9: Impresso | K9: Livro do estudante | L9: 1º ao 3º ano | M9: RABINHO, RABÃO, MACAQUINHO BRINCALHÃO | N9: 36 | O9: 112 | P9: 0.112 | Q9: 205x275 | R9: 80 | S9: 1 | T9: 52201 | U9: 5846.512 | V9: 4.98 | W9: 259960.98 | X9: =VLOOKUP($F9,Agendamento!$B:$J,9,0) -> 46083 | Y9: =COUNTIF(Analise!F:F,'Obras e Acervos'!H9) -> 1
A10: =CONCATENATE(LEFT(C10,12),"-",RIGHT(C10,2),"_",TEXT(X10,"ddmmaaaa"),"_",COUNTIF($C$2:C10,C10)) -> 012974670001-08_12032026_1 | B10: =CONCATENATE(LEFT(C10,12),"-",RIGHT(C10,2),"_",COUNTIF($C$2:C10,C10)) -> 012974670001-08_1 | C10: 01297467000108 | D10: CALIGRAMA EDITORIAL LTDA.-OBÁ EDITORIAL | E10: CATEGORIA 1: OBRAS LIT. DO 1º AO 3º ANO | F10: ALÔ? | G10: IMLE0000301220P230301000000 | H10: 1220L23000030LE | I10: 9786586667158 | J10: Impresso | K10: Livro do estudante | L10: 1º ao 3º ano | M10: ALÔ | N10: 32 | O10: 77 | P10: 0.077 | Q10: 205x275 | R10: 80 | S10: 1 | T10: 49807 | U10: 3835.139 | V10: 4.72 | W10: 235089.04 | X10: =VLOOKUP($F10,Agendamento!$B:$J,9,0) -> 46093 | Y10: =COUNTIF(Analise!F:F,'Obras e Acervos'!H10) -> 1
A11: =CONCATENATE(LEFT(C11,12),"-",RIGHT(C11,2),"_",TEXT(X11,"ddmmaaaa"),"_",COUNTIF($C$2:C11,C11)) -> 155950140001-72_13032026_1 | B11: =CONCATENATE(LEFT(C11,12),"-",RIGHT(C11,2),"_",COUNTIF($C$2:C11,C11)) -> 155950140001-72_1 | C11: 15595014000172 | D11: CULTURA ESCRITA EDIÇÃO E EDUCAÇÃO LTDA ME-CULTURA ESCRITA | E11: CATEGORIA 1: OBRAS LIT. DO 1º AO 3º ANO | F11: RAUL. O LOBINHO | G11: IMLE0000301037P230301000000 | H11: 1037L23000030LE | I11: 9786599676512 | J11: Impresso | K11: Livro do estudante | L11: 1º ao 3º ano | M11: RAUL, O LOBINHO | N11: 32 | O11: 101 | P11: 0.101 | Q11: 275x205 | R11: 80 | S11: 1 | T11: 50989 | U11: 5149.889 | V11: 4.63 | W11: 236079.07 | X11: =VLOOKUP($F11,Agendamento!$B:$J,9,0) -> 46094 | Y11: =COUNTIF(Analise!F:F,'Obras e Acervos'!H11) -> 1
A12: =CONCATENATE(LEFT(C12,12),"-",RIGHT(C12,2),"_",TEXT(X12,"ddmmaaaa"),"_",COUNTIF($C$2:C12,C12)) -> 087310590001-61_24022026_1 | B12: =CONCATENATE(LEFT(C12,12),"-",RIGHT(C12,2),"_",COUNTIF($C$2:C12,C12)) -> 087310590001-61_1 | C12: 08731059000161 | D12: DOMO 72 EMPREENDIMENTOS E PARTICIPACOES LTDA-DOMO 72 EDITORIAL | E12: CATEGORIA 1: OBRAS LIT. DO 1º AO 3º ANO | F12: HAICONTINHOS DE FADAS | G12: IMLE0000301000P230301000000 | H12: 1000L23000030LE | I12: 9786599429125 | J12: Impresso | K12: Livro do estudante | L12: 1º ao 3º ano | M12: HAICONTINHOS DE FADAS | N12: 40 | O12: 121 | P12: 0.121 | Q12: 205x275 | R12: 80 | S12: 1 | T12: 51459 | U12: 6226.539 | V12: 5.35 | W12: 275305.65 | X12: =VLOOKUP($F12,Agendamento!$B:$J,9,0) -> 46077 | Y12: =COUNTIF(Analise!F:F,'Obras e Acervos'!H12) -> 1
A13: =CONCATENATE(LEFT(C13,12),"-",RIGHT(C13,2),"_",TEXT(X13,"ddmmaaaa"),"_",COUNTIF($C$2:C13,C13)) -> 612599580001-96_11022026_1 | B13: =CONCATENATE(LEFT(C13,12),"-",RIGHT(C13,2),"_",COUNTIF($C$2:C13,C13)) -> 612599580001-96_1 | C13: 61259958000196 | D13: EDITORA ATICA S/A-ÁTICA | E13: CATEGORIA 1: OBRAS LIT. DO 1º AO 3º ANO | F13: O FRIO PODE SER QUENTE? | G13: IMLE0000300399P230301000000 | H13: 0399L23000030LE | I13: 9786557670996 | J13: Impresso | K13: Livro do estudante | L13: 1º ao 3º ano | M13: O FRIO PODE SER QUENTE? | N13: 40 | O13: 120 | P13: 0.12 | Q13: 135x205 | R13: 80 | S13: 1 | T13: 54398 | U13: 6527.76 | V13: 4.28 | W13: 232823.44 | X13: =VLOOKUP($F13,Agendamento!$B:$J,9,0) -> 46064 | Y13: =COUNTIF(Analise!F:F,'Obras e Acervos'!H13) -> 1
A14: =CONCATENATE(LEFT(C14,12),"-",RIGHT(C14,2),"_",TEXT(X14,"ddmmaaaa"),"_",COUNTIF($C$2:C14,C14)) -> 436803710001-74_11032026_1 | B14: =CONCATENATE(LEFT(C14,12),"-",RIGHT(C14,2),"_",COUNTIF($C$2:C14,C14)) -> 436803710001-74_1 | C14: 43680371000174 | D14: EDITORA COQUINHO LTDA-COQUINHO | E14: CATEGORIA 1: OBRAS LIT. DO 1º AO 3º ANO | F14: O BRINQUEDO NOVO | G14: IMLE0000300922P230301000000 | H14: 0922L23000030LE | I14: 9786599696718 | J14: Impresso | K14: Livro do estudante | L14: 1º ao 3º ano | M14: O BRINQUEDO NOVO | N14: 32 | O14: 105 | P14: 0.105 | Q14: 205x275 | R14: 80 | S14: 1 | T14: 50337 | U14: 5285.385 | V14: 4.64 | W14: 233563.68 | X14: =VLOOKUP($F14,Agendamento!$B:$J,9,0) -> 46092 | Y14: =COUNTIF(Analise!F:F,'Obras e Acervos'!H14) -> 1
A15: =CONCATENATE(LEFT(C15,12),"-",RIGHT(C15,2),"_",TEXT(X15,"ddmmaaaa"),"_",COUNTIF($C$2:C15,C15)) -> 132061660001-00_25022026_1 | B15: =CONCATENATE(LEFT(C15,12),"-",RIGHT(C15,2),"_",COUNTIF($C$2:C15,C15)) -> 132061660001-00_1 | C15: 13206166000100 | D15: EDITORA GAIVOTA LTDA.-EDITORA GAIVOTA | E15: CATEGORIA 1: OBRAS LIT. DO 1º AO 3º ANO | F15: FESTANÇA | G15: IMLE0000300619P230301000000 | H15: 0619L23000030LE | I15: 9786586686180 | J15: Impresso | K15: Livro do estudante | L15: 1º ao 3º ano | M15: FESTANÇA | N15: 24 | O15: 82 | P15: 0.082 | Q15: 205x275 | R15: 80 | S15: 1 | T15: 52049 | U15: 4268.018 | V15: 3.89 | W15: 202470.61 | X15: =VLOOKUP($F15,Agendamento!$B:$J,9,0) -> 46078 | Y15: =COUNTIF(Analise!F:F,'Obras e Acervos'!H15) -> 1
A16: =CONCATENATE(LEFT(C16,12),"-",RIGHT(C16,2),"_",TEXT(X16,"ddmmaaaa"),"_",COUNTIF($C$2:C16,C16)) -> 051369630001-30_10022026_1 | B16: =CONCATENATE(LEFT(C16,12),"-",RIGHT(C16,2),"_",COUNTIF($C$2:C16,C16)) -> 051369630001-30_1 | C16: 05136963000130 | D16: EDITORA LENDO E APRENDENDO LTDA.- | E16: CATEGORIA 1: OBRAS LIT. DO 1º AO 3º ANO | F16: A MENINA DE NOME ENFEITADO | G16: IMLE0000300543P230301000000 | H16: 0543L23000030LE | I16: 9788562533785 | J16: Impresso | K16: Livro do estudante | L16: 1º ao 3º ano | M16: A MENINA DE NOME ENFEITADO | N16: 32 | O16: 103 | P16: 0.103 | Q16: 205x275 | R16: 80 | S16: 1 | T16: 58488 | U16: 6024.264 | V16: 4.54 | W16: 265535.52 | X16: =VLOOKUP($F16,Agendamento!$B:$J,9,0) -> 46063 | Y16: =COUNTIF(Analise!F:F,'Obras e Acervos'!H16) -> 1
... A806: =CONCATENATE(LEFT(C806,12),"-",RIGHT(C806,2),"_",TEXT(X806,"ddmmaaaa"),"_",COUNTIF($C$2:C806,C806)) -> 171726860001-09_06022026_2 | B806: =CONCATENATE(LEFT(C806,12),"-",RIGHT(C806,2),"_",COUNTIF($C$2:C806,C806)) -> 171726860001-09_2 | C806: 17172686000109 | D806: VMP REPRESENTACOES E COMERCIO LTDA-VMP REPRESENTACOES E COMERCIO | E806: CATEGORIA 2: OBRAS LIT. DO 4º E 5º ANO | F806: O OLHO DA RUA | G806: IMLE0000200667P230302000000 | H806: 0667L23000020LE | I806: 9786584704022 | J806: Impresso | K806: Livro do estudante | L806: 4º e 5º ano | M806: O OLHO DA RUA | N806: 52 | O806: 153 | P806: 0.153 | Q806: 205x275 | R806: 80 | S806: 22 | T806: 23919 | U806: 3659.607 | V806: 8.92 | W806: 213357.48 | X806: =VLOOKUP($F806,Agendamento!$B:$J,9,0) -> 46059 | Y806: =COUNTIF(Analise!F:F,'Obras e Acervos'!H806) -> 1

Sheet Analise
A1: chave | B1: chave | C1: contem | D1: CNPJ | E1: Nome do Fornecedor | F1: SKU | G1: Descrição Item | H1: Acervo | I1: Tiragem | J1: Peso Tiragem | K1: Valor Unitário | L1: Subtotal | M1: Data recebimento | N1: Data Atual | O1: Dias Armazenamento | P1: Meses | Q1: Qtd Paletes Recebidos | R1: Unidades Armazenadas | S1: Valor Dia Armazenagem | T1: Valor Faturamento | U1: Arquivo NF | V1: Link NF | W1: Nome Link NF | X1: CONFERIDO | Y1: TOTAL | Z1: LINK NF | AB1: Data Final Armazenamento | AD1: =CONCATENATE("Total (Paletes até 1000 livros) Até ",TEXT($AB$2,"dd/mm/aaaa")) -> Total (Paletes até 1000 livros) Até 10/10/2026
A2: =CONCATENATE(D2,"_",TEXT(M2,"ddmmaaaa"),"_",COUNTIF($D$2:D2,D2)) -> 056623970001-09_03022026_1 | B2: =CONCATENATE(Analise!D2,"_",COUNTIF(Analise!$D$2:D2,Analise!D2)) -> 056623970001-09_1 | C2: =COUNTIF('Obras e Acervos'!$C:$C,CONCATENATE(LEFT(D2,12),RIGHT(D2,2))) -> 2 | D2: 056623970001-09 | E2: =VLOOKUP($B2,'Obras e Acervos'!$B:$X,3,0) -> ENTREPALAVRAS PRODUÇÃO DE TEXTO -ENTREPALAVRAS | F2: =VLOOKUP($B2,'Obras e Acervos'!$B:$X,7,0) -> 1092L23000030LE | G2: =VLOOKUP($B2,'Obras e Acervos'!$B:$X,5,0) -> HEIDI | H2: =VLOOKUP($B2,'Obras e Acervos'!$B:$X,18,0) -> 2 | I2: =VLOOKUP($B2,'Obras e Acervos'!$B:$X,19,0) -> 47300 | J2: =VLOOKUP($B2,'Obras e Acervos'!$B:$X,20,0) -> 4162.4 | K2: =VLOOKUP($B2,'Obras e Acervos'!$B:$X,21,0) -> 5.02 | L2: =K2*I2 -> 237446 | M2: 46056 | N2: =$AB$2 -> 46305 | O2: =IF(M2="",0,(N2-M2)+1) -> 250 | P2: =O2/30 -> 8.3333333 | Q2: =VLOOKUP($G2,Agendamento!$B:$F,5,0) -> 3 | R2: =IF(U2="",0,ROUNDUP($I2/1000,0)) -> 48 | S2: 2.55 | T2: =O2*R2*S2 -> 30600 | U2: 64237227_20260203_nf_01.pdf | V2: =CONCATENATE("NF/",U2) -> NF/64237227_20260203_nf_01.pdf | W2: =HYPERLINK(CONCATENATE("saida/",U2),CONCATENATE("NF - ",G2)) -> NF - HEIDI | X2: OK | Y2: =COUNTA(W:W)-1 -> 809 | Z2: =COUNTA(U:U)-1 -> 805 | AB2: 46305 | AD2: =SUM(T:T) -> 18552084
A3: =CONCATENATE(D3,"_",TEXT(M3,"ddmmaaaa"),"_",COUNTIF($D$2:D3,D3)) -> 056623970001-09_03022026_2 | B3: =CONCATENATE(Analise!D3,"_",COUNTIF(Analise!$D$2:D3,Analise!D3)) -> 056623970001-09_2 | C3: =COUNTIF('Obras e Acervos'!$C:$C,CONCATENATE(LEFT(D3,12),RIGHT(D3,2))) -> 2 | D3: 056623970001-09 | E3: =VLOOKUP($B3,'Obras e Acervos'!$B:$X,3,0) -> ENTREPALAVRAS PRODUÇÃO DE TEXTO -ENTREPALAVRAS | F3: =VLOOKUP($B3,'Obras e Acervos'!$B:$X,7,0) -> 1093L23000020LE | G3: =VLOOKUP($B3,'Obras e Acervos'!$B:$X,5,0) -> SOFIA DESASTRADA | H3: =VLOOKUP($B3,'Obras e Acervos'!$B:$X,18,0) -> 13 | I3: =VLOOKUP($B3,'Obras e Acervos'!$B:$X,19,0) -> 33938 | J3: =VLOOKUP($B3,'Obras e Acervos'!$B:$X,20,0) -> 2986.544 | K3: =VLOOKUP($B3,'Obras e Acervos'!$B:$X,21,0) -> 5.93 | L3: =K3*I3 -> 201252.34 | M3: 46056 | N3: =$AB$2 -> 46305 | O3: =IF(M3="",0,(N3-M3)+1) -> 250 | P3: =O3/30 -> 8.3333333 | Q3: =VLOOKUP($G3,Agendamento!$B:$F,5,0) -> 4 | R3: =IF(U3="",0,ROUNDUP($I3/1000,0)) -> 34 | S3: 2.55 | T3: =O3*R3*S3 -> 21675 | U3: 64237227_20260203_nf_01.pdf | V3: =CONCATENATE("NF/",U3) -> NF/64237227_20260203_nf_01.pdf | W3: =HYPERLINK(CONCATENATE("saida/",U3),CONCATENATE("NF - ",G3)) -> NF - SOFIA DESASTRADA | X3: OK
A4: =CONCATENATE(D4,"_",TEXT(M4,"ddmmaaaa"),"_",COUNTIF($D$2:D4,D4)) -> 110481170001-61_03022026_1 | B4: =CONCATENATE(Analise!D4,"_",COUNTIF(Analise!$D$2:D4,Analise!D4)) -> 110481170001-61_1 | C4: =COUNTIF('Obras e Acervos'!$C:$C,CONCATENATE(LEFT(D4,12),RIGHT(D4,2))) -> 1 | D4: 110481170001-61 | E4: =VLOOKUP($B4,'Obras e Acervos'!$B:$X,3,0) -> PIPOCA DOCE CASA EDITORIAL LTDA-PIPOCA DOCE | F4: =VLOOKUP($B4,'Obras e Acervos'!$B:$X,7,0) -> 1100L23000030LE | G4: =VLOOKUP($B4,'Obras e Acervos'!$B:$X,5,0) -> SENHOR MOSQUITO E SENHOR ORELHA | H4: =VLOOKUP($B4,'Obras e Acervos'!$B:$X,18,0) -> 8 | I4: =VLOOKUP($B4,'Obras e Acervos'!$B:$X,19,0) -> 33270 | J4: =VLOOKUP($B4,'Obras e Acervos'!$B:$X,20,0) -> 3327 | K4: =VLOOKUP($B4,'Obras e Acervos'!$B:$X,21,0) -> 5.94 | L4: =K4*I4 -> 197623.8 | M4: 46056 | N4: =$AB$2 -> 46305 | O4: =IF(M4="",0,(N4-M4)+1) -> 250 | P4: =O4/30 -> 8.3333333 | Q4: =VLOOKUP($G4,Agendamento!$B:$F,5,0) -> 4 | R4: =IF(U4="",0,ROUNDUP($I4/1000,0)) -> 34 | S4: 2.55 | T4: =O4*R4*S4 -> 21675 | U4: 64237227_20260203_nf_02.pdf | V4: =CONCATENATE("NF/",U4) -> NF/64237227_20260203_nf_02.pdf | W4: =HYPERLINK(CONCATENATE("saida/",U4),CONCATENATE("NF - ",G4)) -> NF - SENHOR MOSQUITO E SENHOR ORELHA | X4: OK
A5: =CONCATENATE(D5,"_",TEXT(M5,"ddmmaaaa"),"_",COUNTIF($D$2:D5,D5)) -> 436787690001-76_03022026_1 | B5: =CONCATENATE(Analise!D5,"_",COUNTIF(Analise!$D$2:D5,Analise!D5)) -> 436787690001-76_1 | C5: =COUNTIF('Obras e Acervos'!$C:$C,CONCATENATE(LEFT(D5,12),RIGHT(D5,2))) -> 1 | D5: 436787690001-76 | E5: =VLOOKUP($B5,'Obras e Acervos'!$B:$X,3,0) -> MARCO ZERO EDITORA LTDA-MARCO ZERO EDITORA | F5: =VLOOKUP($B5,'Obras e Acervos'!$B:$X,7,0) -> 0591L23000030LE | G5: =VLOOKUP($B5,'Obras e Acervos'!$B:$X,5,0) -> O AMOR TEM COR? | H5: =VLOOKUP($B5,'Obras e Acervos'!$B:$X,18,0) -> 6 | I5: =VLOOKUP($B5,'Obras e Acervos'!$B:$X,19,0) -> 63081 | J5: =VLOOKUP($B5,'Obras e Acervos'!$B:$X,20,0) -> 6623.505 | K5: =VLOOKUP($B5,'Obras e Acervos'!$B:$X,21,0) -> 4.27 | L5: =K5*I5 -> 269355.87 | M5: 46056 | N5: =$AB$2 -> 46305 | O5: =IF(M5="",0,(N5-M5)+1) -> 250 | P5: =O5/30 -> 8.3333333 | Q5: =VLOOKUP($G5,Agendamento!$B:$F,5,0) -> 7 | R5: =IF(U5="",0,ROUNDUP($I5/1000,0)) -> 64 | S5: 2.55 | T5: =O5*R5*S5 -> 40800 | U5: 64237227_20260203_nf_03.pdf | V5: =CONCATENATE("NF/",U5) -> NF/64237227_20260203_nf_03.pdf | W5: =HYPERLINK(CONCATENATE("saida/",U5),CONCATENATE("NF - ",G5)) -> NF - O AMOR TEM COR? | X5: OK
A6: =CONCATENATE(D6,"_",TEXT(M6,"ddmmaaaa"),"_",COUNTIF($D$2:D6,D6)) -> 442226150001-38_03022026_1 | B6: =CONCATENATE(Analise!D6,"_",COUNTIF(Analise!$D$2:D6,Analise!D6)) -> 442226150001-38_1 | C6: =COUNTIF('Obras e Acervos'!$C:$C,CONCATENATE(LEFT(D6,12),RIGHT(D6,2))) -> 2 | D6: 442226150001-38 | E6: =VLOOKUP($B6,'Obras e Acervos'!$B:$X,3,0) -> CHUVINHA EDITORA LTDA.-CHUVINHA | F6: =VLOOKUP($B6,'Obras e Acervos'!$B:$X,7,0) -> 1240L23000030LE | G6: =VLOOKUP($B6,'Obras e Acervos'!$B:$X,5,0) -> ZIGGY E O SHOW AO LUAR | H6: =VLOOKUP($B6,'Obras e Acervos'!$B:$X,18,0) -> 8 | I6: =VLOOKUP($B6,'Obras e Acervos'!$B:$X,19,0) -> 33180 | J6: =VLOOKUP($B6,'Obras e Acervos'!$B:$X,20,0) -> 2554.86 | K6: =VLOOKUP($B6,'Obras e Acervos'!$B:$X,21,0) -> 5.96 | L6: =K6*I6 -> 197752.8 | M6: 46056 | N6: =$AB$2 -> 46305 | O6: =IF(M6="",0,(N6-M6)+1) -> 250 | P6: =O6/30 -> 8.3333333 | Q6: =VLOOKUP($G6,Agendamento!$B:$F,5,0) -> 4 | R6: =IF(U6="",0,ROUNDUP($I6/1000,0)) -> 34 | S6: 2.55 | T6: =O6*R6*S6 -> 21675 | U6: 64237227_20260203_nf_04.pdf | V6: =CONCATENATE("NF/",U6) -> NF/64237227_20260203_nf_04.pdf | W6: =HYPERLINK(CONCATENATE("saida/",U6),CONCATENATE("NF - ",G6)) -> NF - ZIGGY E O SHOW AO LUAR | X6: OK
A7: =CONCATENATE(D7,"_",TEXT(M7,"ddmmaaaa"),"_",COUNTIF($D$2:D7,D7)) -> 442226150001-38_03022026_2 | B7: =CONCATENATE(Analise!D7,"_",COUNTIF(Analise!$D$2:D7,Analise!D7)) -> 442226150001-38_2 | C7: =COUNTIF('Obras e Acervos'!$C:$C,CONCATENATE(LEFT(D7,12),RIGHT(D7,2))) -> 2 | D7: 442226150001-38 | E7: =VLOOKUP($B7,'Obras e Acervos'!$B:$X,3,0) -> CHUVINHA EDITORA LTDA.-CHUVINHA | F7: =VLOOKUP($B7,'Obras e Acervos'!$B:$X,7,0) -> 1241L23000020LE | G7: =VLOOKUP($B7,'Obras e Acervos'!$B:$X,5,0) -> O SECADOR DE LIVROS | H7: =VLOOKUP($B7,'Obras e Acervos'!$B:$X,18,0) -> 12 | I7: =VLOOKUP($B7,'Obras e Acervos'!$B:$X,19,0) -> 32236 | J7: =VLOOKUP($B7,'Obras e Acervos'!$B:$X,20,0) -> 2482.172 | K7: =VLOOKUP($B7,'Obras e Acervos'!$B:$X,21,0) -> 6.34 | L7: =K7*I7 -> 204376.24 | M7: 46056 | N7: =$AB$2 -> 46305 | O7: =IF(M7="",0,(N7-M7)+1) -> 250 | P7: =O7/30 -> 8.3333333 | Q7: =VLOOKUP($G7,Agendamento!$B:$F,5,0) -> 4 | R7: =IF(U7="",0,ROUNDUP($I7/1000,0)) -> 33 | S7: 2.55 | T7: =O7*R7*S7 -> 21037.5 | U7: 64237227_20260203_nf_04.pdf | V7: =CONCATENATE("NF/",U7) -> NF/64237227_20260203_nf_04.pdf | W7: =HYPERLINK(CONCATENATE("saida/",U7),CONCATENATE("NF - ",G7)) -> NF - O SECADOR DE LIVROS | X7: OK
A8: =CONCATENATE(D8,"_",TEXT(M8,"ddmmaaaa"),"_",COUNTIF($D$2:D8,D8)) -> 442721010001-97_03022026_1 | B8: =CONCATENATE(Analise!D8,"_",COUNTIF(Analise!$D$2:D8,Analise!D8)) -> 442721010001-97_1 | C8: =COUNTIF('Obras e Acervos'!$C:$C,CONCATENATE(LEFT(D8,12),RIGHT(D8,2))) -> 1 | D8: 442721010001-97 | E8: =VLOOKUP($B8,'Obras e Acervos'!$B:$X,3,0) -> BOTO ROSA EDITORA LTDA.-BOTO ROSA | F8: =VLOOKUP($B8,'Obras e Acervos'!$B:$X,7,0) -> 1238L23000030LE | G8: =VLOOKUP($B8,'Obras e Acervos'!$B:$X,5,0) -> FRED, O PAPA-FORMIGA | H8: =VLOOKUP($B8,'Obras e Acervos'!$B:$X,18,0) -> 8 | I8: =VLOOKUP($B8,'Obras e Acervos'!$B:$X,19,0) -> 33437 | J8: =VLOOKUP($B8,'Obras e Acervos'!$B:$X,20,0) -> 2574.649 | K8: =VLOOKUP($B8,'Obras e Acervos'!$B:$X,21,0) -> 5.94 | L8: =K8*I8 -> 198615.78 | M8: 46056 | N8: =$AB$2 -> 46305 | O8: =IF(M8="",0,(N8-M8)+1) -> 250 | P8: =O8/30 -> 8.3333333 | Q8: =VLOOKUP($G8,Agendamento!$B:$F,5,0) -> 4 | R8: =IF(U8="",0,ROUNDUP($I8/1000,0)) -> 34 | S8: 2.55 | T8: =O8*R8*S8 -> 21675 | U8: 64237227_20260203_nf_06.pdf | V8: =CONCATENATE("NF/",U8) -> NF/64237227_20260203_nf_06.pdf | W8: =HYPERLINK(CONCATENATE("saida/",U8),CONCATENATE("NF - ",G8)) -> NF - FRED, O PAPA-FORMIGA | X8: OK
A9: =CONCATENATE(D9,"_",TEXT(M9,"ddmmaaaa"),"_",COUNTIF($D$2:D9,D9)) -> 438867580001-81_03022026_1 | B9: =CONCATENATE(Analise!D9,"_",COUNTIF(Analise!$D$2:D9,Analise!D9)) -> 438867580001-81_1 | C9: =COUNTIF('Obras e Acervos'!$C:$C,CONCATENATE(LEFT(D9,12),RIGHT(D9,2))) -> 1 | D9: 438867580001-81 | E9: =VLOOKUP($B9,'Obras e Acervos'!$B:$X,3,0) -> EDITORA CORALINDA LTDA-CORALINDA | F9: =VLOOKUP($B9,'Obras e Acervos'!$B:$X,7,0) -> 1050L23000030LE | G9: =VLOOKUP($B9,'Obras e Acervos'!$B:$X,5,0) -> NUMA TERRA ESTRANHA | H9: =VLOOKUP($B9,'Obras e Acervos'!$B:$X,18,0) -> 2 | I9: =VLOOKUP($B9,'Obras e Acervos'!$B:$X,19,0) -> 43437 | J9: =VLOOKUP($B9,'Obras e Acervos'!$B:$X,20,0) -> 4995.255 | K9: =VLOOKUP($B9,'Obras e Acervos'!$B:$X,21,0) -> 5.48 | L9: =K9*I9 -> 238034.76 | M9: 46056 | N9: =$AB$2 -> 46305 | O9: =IF(M9="",0,(N9-M9)+1) -> 250 | P9: =O9/30 -> 8.3333333 | Q9: =VLOOKUP($G9,Agendamento!$B:$F,5,0) -> 5 | R9: =IF(U9="",0,ROUNDUP($I9/1000,0)) -> 44 | S9: 2.55 | T9: =O9*R9*S9 -> 28050 | U9: 64237227_20260203_nf_08.pdf | V9: =CONCATENATE("NF/",U9) -> NF/64237227_20260203_nf_08.pdf | W9: =HYPERLINK(CONCATENATE("saida/",U9),CONCATENATE("NF - ",G9)) -> NF - NUMA TERRA ESTRANHA | X9: OK
A10: =CONCATENATE(D10,"_",TEXT(M10,"ddmmaaaa"),"_",COUNTIF($D$2:D10,D10)) -> 011836130001-74_03022026_1 | B10: =CONCATENATE(Analise!D10,"_",COUNTIF(Analise!$D$2:D10,Analise!D10)) -> 011836130001-74_1 | C10: =COUNTIF('Obras e Acervos'!$C:$C,CONCATENATE(LEFT(D10,12),RIGHT(D10,2))) -> 2 | D10: 011836130001-74 | E10: =VLOOKUP($B10,'Obras e Acervos'!$B:$X,3,0) -> EDIOURO PUBLICACOES DE PASSATEMPOS E MULTIMIDIA LTDA-EDIPASS | F10: =VLOOKUP($B10,'Obras e Acervos'!$B:$X,7,0) -> 0361L23000030LE | G10: =VLOOKUP($B10,'Obras e Acervos'!$B:$X,5,0) -> EM BOCA FECHADA NÃO ENTRA ESTRELA | H10: =VLOOKUP($B10,'Obras e Acervos'!$B:$X,18,0) -> 9 | I10: =VLOOKUP($B10,'Obras e Acervos'!$B:$X,19,0) -> 33219 | J10: =VLOOKUP($B10,'Obras e Acervos'!$B:$X,20,0) -> 2624.301 | K10: =VLOOKUP($B10,'Obras e Acervos'!$B:$X,21,0) -> 5 | L10: =K10*I10 -> 166095 | M10: 46056 | N10: =$AB$2 -> 46305 | O10: =IF(M10="",0,(N10-M10)+1) -> 250 | P10: =O10/30 -> 8.3333333 | Q10: =VLOOKUP($G10,Agendamento!$B:$F,5,0) -> 2 | R10: =IF(U10="",0,ROUNDUP($I10/1000,0)) -> 34 | S10: 2.55 | T10: =O10*R10*S10 -> 21675 | U10: 64237227_20260203_nf_09.pdf | V10: =CONCATENATE("NF/",U10) -> NF/64237227_20260203_nf_09.pdf | W10: =HYPERLINK(CONCATENATE("saida/",U10),CONCATENATE("NF - ",G10)) -> NF - EM BOCA FECHADA NÃO ENTRA ESTRELA | X10: OK
A11: =CONCATENATE(D11,"_",TEXT(M11,"ddmmaaaa"),"_",COUNTIF($D$2:D11,D11)) -> 011836130001-74_03022026_2 | B11: =CONCATENATE(Analise!D11,"_",COUNTIF(Analise!$D$2:D11,Analise!D11)) -> 011836130001-74_2 | C11: =COUNTIF('Obras e Acervos'!$C:$C,CONCATENATE(LEFT(D11,12),RIGHT(D11,2))) -> 2 | D11: 011836130001-74 | E11: =VLOOKUP($B11,'Obras e Acervos'!$B:$X,3,0) -> EDIOURO PUBLICACOES DE PASSATEMPOS E MULTIMIDIA LTDA-EDIPASS | F11: =VLOOKUP($B11,'Obras e Acervos'!$B:$X,7,0) -> 0362L23000020LE | G11: =VLOOKUP($B11,'Obras e Acervos'!$B:$X,5,0) -> AMOR PLENILUNAR: NO JARDIM DO SONHO E DO ESQUECIMENTO | H11: =VLOOKUP($B11,'Obras e Acervos'!$B:$X,18,0) -> 11 | I11: =VLOOKUP($B11,'Obras e Acervos'!$B:$X,19,0) -> 32589 | J11: =VLOOKUP($B11,'Obras e Acervos'!$B:$X,20,0) -> 3128.544 | K11: =VLOOKUP($B11,'Obras e Acervos'!$B:$X,21,0) -> 5.89 | L11: =K11*I11 -> 191949.21 | M11: 46056 | N11: =$AB$2 -> 46305 | O11: =IF(M11="",0,(N11-M11)+1) -> 250 | P11: =O11/30 -> 8.3333333 | Q11: =VLOOKUP($G11,Agendamento!$B:$F,5,0) -> 6 | R11: =IF(U11="",0,ROUNDUP($I11/1000,0)) -> 33 | S11: 2.55 | T11: =O11*R11*S11 -> 21037.5 | U11: 64237227_20260203_nf_09.pdf | V11: =CONCATENATE("NF/",U11) -> NF/64237227_20260203_nf_09.pdf | W11: =HYPERLINK(CONCATENATE("saida/",U11),CONCATENATE("NF - ",G11)) -> NF - AMOR PLENILUNAR: NO JARDIM DO SONHO E DO ESQUECIMENTO | X11: OK
A12: =CONCATENATE(D12,"_",TEXT(M12,"ddmmaaaa"),"_",COUNTIF($D$2:D12,D12)) -> 011836140001-19_03022026_1 | B12: =CONCATENATE(Analise!D12,"_",COUNTIF(Analise!$D$2:D12,Analise!D12)) -> 011836140001-19_1 | C12: =COUNTIF('Obras e Acervos'!$C:$C,CONCATENATE(LEFT(D12,12),RIGHT(D12,2))) -> 2 | D12: 011836140001-19 | E12: =VLOOKUP($B12,'Obras e Acervos'!$B:$X,3,0) -> EDIOURO PUBLICACOES DE LAZER E CULTURA LTDA-NÃO HÁ | F12: =VLOOKUP($B12,'Obras e Acervos'!$B:$X,7,0) -> 0376L23000030LE | G12: =VLOOKUP($B12,'Obras e Acervos'!$B:$X,5,0) -> TRAVATROVAS | H12: =VLOOKUP($B12,'Obras e Acervos'!$B:$X,18,0) -> 10 | I12: =VLOOKUP($B12,'Obras e Acervos'!$B:$X,19,0) -> 33010 | J12: =VLOOKUP($B12,'Obras e Acervos'!$B:$X,20,0) -> 1551.47 | K12: =VLOOKUP($B12,'Obras e Acervos'!$B:$X,21,0) -> 5.03 | L12: =K12*I12 -> 166040.3 | M12: 46056 | N12: =$AB$2 -> 46305 | O12: =IF(M12="",0,(N12-M12)+1) -> 250 | P12: =O12/30 -> 8.3333333 | Q12: =VLOOKUP($G12,Agendamento!$B:$F,5,0) -> 3 | R12: =IF(U12="",0,ROUNDUP($I12/1000,0)) -> 34 | S12: 2.55 | T12: =O12*R12*S12 -> 21675 | U12: 64237227_20260203_nf_10.pdf | V12: =CONCATENATE("NF/",U12) -> NF/64237227_20260203_nf_10.pdf | W12: =HYPERLINK(CONCATENATE("saida/",U12),CONCATENATE("NF - ",G12)) -> NF - TRAVATROVAS | X12: OK
A13: =CONCATENATE(D13,"_",TEXT(M13,"ddmmaaaa"),"_",COUNTIF($D$2:D13,D13)) -> 011836140001-19_03022026_2 | B13: =CONCATENATE(Analise!D13,"_",COUNTIF(Analise!$D$2:D13,Analise!D13)) -> 011836140001-19_2 | C13: =COUNTIF('Obras e Acervos'!$C:$C,CONCATENATE(LEFT(D13,12),RIGHT(D13,2))) -> 2 | D13: 011836140001-19 | E13: =VLOOKUP($B13,'Obras e Acervos'!$B:$X,3,0) -> EDIOURO PUBLICACOES DE LAZER E CULTURA LTDA-NÃO HÁ | F13: =VLOOKUP($B13,'Obras e Acervos'!$B:$X,7,0) -> 0377L23000020LE | G13: =VLOOKUP($B13,'Obras e Acervos'!$B:$X,5,0) -> O REI DAS PALAVRAS | H13: =VLOOKUP($B13,'Obras e Acervos'!$B:$X,18,0) -> 22 | I13: =VLOOKUP($B13,'Obras e Acervos'!$B:$X,19,0) -> 23707 | J13: =VLOOKUP($B13,'Obras e Acervos'!$B:$X,20,0) -> 4670.279 | K13: =VLOOKUP($B13,'Obras e Acervos'!$B:$X,21,0) -> 12.02 | L13: =K13*I13 -> 284958.14 | M13: 46056 | N13: =$AB$2 -> 46305 | O13: =IF(M13="",0,(N13-M13)+1) -> 250 | P13: =O13/30 -> 8.3333333 | Q13: =VLOOKUP($G13,Agendamento!$B:$F,5,0) -> 6 | R13: =IF(U13="",0,ROUNDUP($I13/1000,0)) -> 24 | S13: 2.55 | T13: =O13*R13*S13 -> 15300 | U13: 64237227_20260203_nf_10.pdf | V13: =CONCATENATE("NF/",U13) -> NF/64237227_20260203_nf_10.pdf | W13: =HYPERLINK(CONCATENATE("saida/",U13),CONCATENATE("NF - ",G13)) -> NF - O REI DAS PALAVRAS | X13: OK
A14: =CONCATENATE(D14,"_",TEXT(M14,"ddmmaaaa"),"_",COUNTIF($D$2:D14,D14)) -> 041609200001-28_03022026_1 | B14: =CONCATENATE(Analise!D14,"_",COUNTIF(Analise!$D$2:D14,Analise!D14)) -> 041609200001-28_1 | C14: =COUNTIF('Obras e Acervos'!$C:$C,CONCATENATE(LEFT(D14,12),RIGHT(D14,2))) -> 2 | D14: 041609200001-28 | E14: =VLOOKUP($B14,'Obras e Acervos'!$B:$X,3,0) -> EDIOURO GRAFICA E EDITORA PARTICIPACOES S.A -EDIPAR | F14: =VLOOKUP($B14,'Obras e Acervos'!$B:$X,7,0) -> 0369L23000030LE | G14: =VLOOKUP($B14,'Obras e Acervos'!$B:$X,5,0) -> A TURMA DO ABC | H14: =VLOOKUP($B14,'Obras e Acervos'!$B:$X,18,0) -> 8 | I14: =VLOOKUP($B14,'Obras e Acervos'!$B:$X,19,0) -> 41754 | J14: =VLOOKUP($B14,'Obras e Acervos'!$B:$X,20,0) -> 4008.384 | K14: =VLOOKUP($B14,'Obras e Acervos'!$B:$X,21,0) -> 5.31 | L14: =K14*I14 -> 221713.74 | M14: 46056 | N14: =$AB$2 -> 46305 | O14: =IF(M14="",0,(N14-M14)+1) -> 250 | P14: =O14/30 -> 8.3333333 | Q14: =VLOOKUP($G14,Agendamento!$B:$F,5,0) -> 4 | R14: =IF(U14="",0,ROUNDUP($I14/1000,0)) -> 42 | S14: 2.55 | T14: =O14*R14*S14 -> 26775 | U14: 64237227_20260203_nf_11.pdf | V14: =CONCATENATE("NF/",U14) -> NF/64237227_20260203_nf_11.pdf | W14: =HYPERLINK(CONCATENATE("saida/",U14),CONCATENATE("NF - ",G14)) -> NF - A TURMA DO ABC | X14: OK
... A17: =CONCATENATE(D17,"_",TEXT(M17,"ddmmaaaa"),"_",COUNTIF($D$2:D17,D17)) -> 436814000001-12_05022026_1 | B17: =CONCATENATE(Analise!D17,"_",COUNTIF(Analise!$D$2:D17,Analise!D17)) -> 436814000001-12_1 | C17: =COUNTIF('Obras e Acervos'!$C:$C,CONCATENATE(LEFT(D17,12),RIGHT(D17,2))) -> 1 | D17: 436814000001-12 | E17: =VLOOKUP($B17,'Obras e Acervos'!$B:$X,3,0) -> TACACÁ EDITORIAL LTDA-TACACA EDITORIAL | F17: =VLOOKUP($B17,'Obras e Acervos'!$B:$X,7,0) -> 1275L23000030LE | G17: =VLOOKUP($B17,'Obras e Acervos'!$B:$X,5,0) -> AMOR EXPLICADINHO | H17: =VLOOKUP($B17,'Obras e Acervos'!$B:$X,18,0) -> 8 | I17: =VLOOKUP($B17,'Obras e Acervos'!$B:$X,19,0) -> 33225 | J17: =VLOOKUP($B17,'Obras e Acervos'!$B:$X,20,0) -> 3488.625 | K17: =VLOOKUP($B17,'Obras e Acervos'!$B:$X,21,0) -> 5.94 | L17: =K17*I17 -> 197356.5 | M17: 46058 | N17: =$AB$2 -> 46305 | O17: =IF(M17="",0,(N17-M17)+1) -> 248 | P17: =O17/30 -> 8.2666667 | Q17: =VLOOKUP($G17,Agendamento!$B:$F,5,0) -> 4 | R17: =IF(U17="",0,ROUNDUP($I17/1000,0)) -> 34 | S17: 2.55 | T17: =O17*R17*S17 -> 21501.6 | U17: 64237227_20260205_nf_01.pdf | V17: =CONCATENATE("NF/",U17) -> NF/64237227_20260205_nf_01.pdf | W17: =HYPERLINK(CONCATENATE("saida/",U17),CONCATENATE("NF - ",G17)) -> NF - AMOR EXPLICADINHO | X17: OK
A18: =CONCATENATE(D18,"_",TEXT(M18,"ddmmaaaa"),"_",COUNTIF($D$2:D18,D18)) -> 610974320001-57_05022026_1 | B18: =CONCATENATE(Analise!D18,"_",2) -> 610974320001-57_2 | C18: =COUNTIF('Obras e Acervos'!$C:$C,CONCATENATE(LEFT(D18,12),RIGHT(D18,2))) -> 2 | D18: 610974320001-57 | E18: =VLOOKUP($B18,'Obras e Acervos'!$B:$X,3,0) -> KITS EDITORA COMÉRCIO E INDÚSTRIA LTDA-KIT´S EDITORA | F18: =VLOOKUP($B18,'Obras e Acervos'!$B:$X,7,0) -> 0788L23000020LE | G18: =VLOOKUP($B18,'Obras e Acervos'!$B:$X,5,0) -> COMIDAS ESTRANHUDAS | H18: =VLOOKUP($B18,'Obras e Acervos'!$B:$X,18,0) -> 21 | I18: =VLOOKUP($B18,'Obras e Acervos'!$B:$X,19,0) -> 23799 | J18: =VLOOKUP($B18,'Obras e Acervos'!$B:$X,20,0) -> 2689.287 | K18: =VLOOKUP($B18,'Obras e Acervos'!$B:$X,21,0) -> 11.91 | L18: =K18*I18 -> 283446.09 | M18: 46058 | N18: =$AB$2 -> 46305 | O18: =IF(M18="",0,(N18-M18)+1) -> 248 | P18: =O18/30 -> 8.2666667 | Q18: =VLOOKUP($G18,Agendamento!$B:$F,5,0) -> 4 | R18: =IF(U18="",0,ROUNDUP($I18/1000,0)) -> 24 | S18: 2.55 | T18: =O18*R18*S18 -> 15177.6 | U18: 64237227_20260205_nf_02.pdf | V18: =CONCATENATE("NF/",U18) -> NF/64237227_20260205_nf_02.pdf | W18: =HYPERLINK(CONCATENATE("saida/",U18),CONCATENATE("NF - ",G18)) -> NF - COMIDAS ESTRANHUDAS | X18: CORRIGIDO
A19: =CONCATENATE(D19,"_",TEXT(M19,"ddmmaaaa"),"_",COUNTIF($D$2:D19,D19)) -> 048643160001-82_05022026_1 | B19: =CONCATENATE(Analise!D19,"_",COUNTIF(Analise!$D$2:D19,Analise!D19)+1) -> 048643160001-82_2 | C19: =COUNTIF('Obras e Acervos'!$C:$C,CONCATENATE(LEFT(D19,12),RIGHT(D19,2))) -> 2 | D19: 048643160001-82 | E19: =VLOOKUP($B19,'Obras e Acervos'!$B:$X,3,0) -> EDITORA E GRAFICA INDICO LTDA-EDITORA INDICO | F19: =VLOOKUP($B19,'Obras e Acervos'!$B:$X,7,0) -> 0456L23000020LE | G19: =VLOOKUP($B19,'Obras e Acervos'!$B:$X,5,0) -> O BREJO DAS TABOAS | H19: =VLOOKUP($B19,'Obras e Acervos'!$B:$X,18,0) -> 11 | I19: =VLOOKUP($B19,'Obras e Acervos'!$B:$X,19,0) -> 32483 | J19: =VLOOKUP($B19,'Obras e Acervos'!$B:$X,20,0) -> 3345.749 | K19: =VLOOKUP($B19,'Obras e Acervos'!$B:$X,21,0) -> 6.34 | L19: =K19*I19 -> 205942.22 | M19: 46058 | N19: =$AB$2 -> 46305 | O19: =IF(M19="",0,(N19-M19)+1) -> 248 | P19: =O19/30 -> 8.2666667 | Q19: =VLOOKUP($G19,Agendamento!$B:$F,5,0) -> 4 | R19: =IF(U19="",0,ROUNDUP($I19/1000,0)) -> 33 | S19: 2.55 | T19: =O19*R19*S19 -> 20869.2 | U19: 64237227_20260205_nf_03.pdf | V19: =CONCATENATE("NF/",U19) -> NF/64237227_20260205_nf_03.pdf | W19: =HYPERLINK(CONCATENATE("saida/",U19),CONCATENATE("NF - ",G19)) -> NF - O BREJO DAS TABOAS | X19: CORRIGIDO
A20: =CONCATENATE(D20,"_",TEXT(M20,"ddmmaaaa"),"_",COUNTIF($D$2:D20,D20)) -> 170777540001-42_05022026_1 | B20: =CONCATENATE(Analise!D20,"_",COUNTIF(Analise!$D$2:D20,Analise!D20)+1) -> 170777540001-42_2 | C20: =COUNTIF('Obras e Acervos'!$C:$C,CONCATENATE(LEFT(D20,12),RIGHT(D20,2))) -> 2 | D20: 170777540001-42 | E20: =VLOOKUP($B20,'Obras e Acervos'!$B:$X,3,0) -> SG-AMARANTE EDITORIAL LTDA-SG-AMARANTE | F20: =VLOOKUP($B20,'Obras e Acervos'!$B:$X,7,0) -> 0957L23000020LE | G20: =VLOOKUP($B20,'Obras e Acervos'!$B:$X,5,0) -> É TUDO VERDADE! (OU SERÁ MENTIRA?) | H20: =VLOOKUP($B20,'Obras e Acervos'!$B:$X,18,0) -> 11 | I20: =VLOOKUP($B20,'Obras e Acervos'!$B:$X,19,0) -> 39724 | J20: =VLOOKUP($B20,'Obras e Acervos'!$B:$X,20,0) -> 4171.02 | K20: =VLOOKUP($B20,'Obras e Acervos'!$B:$X,21,0) -> 5.44 | L20: =K20*I20 -> 216098.56 | M20: 46058 | N20: =$AB$2 -> 46305 | O20: =IF(M20="",0,(N20-M20)+1) -> 248 | P20: =O20/30 -> 8.2666667 | Q20: =VLOOKUP($G20,Agendamento!$B:$F,5,0) -> 5 | R20: =IF(U20="",0,ROUNDUP($I20/1000,0)) -> 40 | S20: 2.55 | T20: =O20*R20*S20 -> 25296 | U20: 64237227_20260205_nf_04.pdf | V20: =CONCATENATE("NF/",U20) -> NF/64237227_20260205_nf_04.pdf | W20: =HYPERLINK(CONCATENATE("saida/",U20),CONCATENATE("NF - ",G20)) -> NF - É TUDO VERDADE! (OU SERÁ MENTIRA?) | X20: CORRIGIDO
A21: =CONCATENATE(D21,"_",TEXT(M21,"ddmmaaaa"),"_",COUNTIF($D$2:D21,D21)) -> 339677750001-90_05022026_1 | B21: =CONCATENATE(Analise!D21,"_",COUNTIF(Analise!$D$2:D21,Analise!D21)+1) -> 339677750001-90_2 | C21: =COUNTIF('Obras e Acervos'!$C:$C,CONCATENATE(LEFT(D21,12),RIGHT(D21,2))) -> 2 | D21: 339677750001-90 | E21: =VLOOKUP($B21,'Obras e Acervos'!$B:$X,3,0) -> GUTENBERG DISTRIBUIDORA DE LIVROS LTDA.-YELLOWFANTE | F21: =VLOOKUP($B21,'Obras e Acervos'!$B:$X,7,0) -> 0987L23000020LE | G21: =VLOOKUP($B21,'Obras e Acervos'!$B:$X,5,0) -> O MAR DE MANU | H21: =VLOOKUP($B21,'Obras e Acervos'!$B:$X,18,0) -> 22 | I21: =VLOOKUP($B21,'Obras e Acervos'!$B:$X,19,0) -> 24025 | J21: =VLOOKUP($B21,'Obras e Acervos'!$B:$X,20,0) -> 2522.625 | K21: =VLOOKUP($B21,'Obras e Acervos'!$B:$X,21,0) -> 6.57 | L21: =K21*I21 -> 157844.25 | M21: 46058 | N21: =$AB$2 -> 46305 | O21: =IF(M21="",0,(N21-M21)+1) -> 248 | P21: =O21/30 -> 8.2666667 | Q21: =VLOOKUP($G21,Agendamento!$B:$F,5,0) -> 3 | R21: =IF(U21="",0,ROUNDUP($I21/1000,0)) -> 25 | S21: 2.55 | T21: =O21*R21*S21 -> 15810 | U21: 64237227_20260205_nf_05.pdf | V21: =CONCATENATE("NF/",U21) -> NF/64237227_20260205_nf_05.pdf | W21: =HYPERLINK(CONCATENATE("saida/",U21),CONCATENATE("NF - ",G21)) -> NF - O MAR DE MANU | X21: CORRIGIDO
A22: =CONCATENATE(D22,"_",TEXT(M22,"ddmmaaaa"),"_",COUNTIF($D$2:D22,D22)) -> 387460380001-80_05022026_1 | B22: =CONCATENATE(Analise!D22,"_",COUNTIF(Analise!$D$2:D22,Analise!D22)) -> 387460380001-80_1 | C22: =COUNTIF('Obras e Acervos'!$C:$C,CONCATENATE(LEFT(D22,12),RIGHT(D22,2))) -> 2 | D22: 387460380001-80 | E22: =VLOOKUP($B22,'Obras e Acervos'!$B:$X,3,0) -> EDITORA GUTENBERG LTDA.-GUTENBERG | F22: =VLOOKUP($B22,'Obras e Acervos'!$B:$X,7,0) -> 0720L23000030LE | G22: =VLOOKUP($B22,'Obras e Acervos'!$B:$X,5,0) -> A CASA QUE ASSOVIAVA | H22: =VLOOKUP($B22,'Obras e Acervos'!$B:$X,18,0) -> 4 | I22: =VLOOKUP($B22,'Obras e Acervos'!$B:$X,19,0) -> 48444 | J22: =VLOOKUP($B22,'Obras e Acervos'!$B:$X,20,0) -> 5086.62 | K22: =VLOOKUP($B22,'Obras e Acervos'!$B:$X,21,0) -> 4.75 | L22: =K22*I22 -> 230109 | M22: 46058 | N22: =$AB$2 -> 46305 | O22: =IF(M22="",0,(N22-M22)+1) -> 248 | P22: =O22/30 -> 8.2666667 | Q22: =VLOOKUP($G22,Agendamento!$B:$F,5,0) -> 6 | R22: =IF(U22="",0,ROUNDUP($I22/1000,0)) -> 49 | S22: 2.55 | T22: =O22*R22*S22 -> 30987.6 | U22: 64237227_20260205_nf_06.pdf | V22: =CONCATENATE("NF/",U22) -> NF/64237227_20260205_nf_06.pdf | W22: =HYPERLINK(CONCATENATE("saida/",U22),CONCATENATE("NF - ",G22)) -> NF - A CASA QUE ASSOVIAVA | X22: OK
A23: =CONCATENATE(D23,"_",TEXT(M23,"ddmmaaaa"),"_",COUNTIF($D$2:D23,D23)) -> 227694490001-51_05022026_1 | B23: =CONCATENATE(Analise!D23,"_",COUNTIF(Analise!$D$2:D23,Analise!D23)+1) -> 227694490001-51_2 | C23: =COUNTIF('Obras e Acervos'!$C:$C,CONCATENATE(LEFT(D23,12),RIGHT(D23,2))) -> 2 | D23: 227694490001-51 | E23: =VLOOKUP($B23,'Obras e Acervos'!$B:$X,3,0) -> EDITORA MADREPEROLA LTDA-EDITORA MADREPÉROLA | F23: =VLOOKUP($B23,'Obras e Acervos'!$B:$X,7,0) -> 1249L23000020LE | G23: =VLOOKUP($B23,'Obras e Acervos'!$B:$X,5,0) -> INÁCIO! LARGA ESSE CELULAR | H23: =VLOOKUP($B23,'Obras e Acervos'!$B:$X,18,0) -> 19 | I23: =VLOOKUP($B23,'Obras e Acervos'!$B:$X,19,0) -> 36587 | J23: =VLOOKUP($B23,'Obras e Acervos'!$B:$X,20,0) -> 3658.7 | K23: =VLOOKUP($B23,'Obras e Acervos'!$B:$X,21,0) -> 5.85 | L23: =K23*I23 -> 214033.95 | M23: 46058 | N23: =$AB$2 -> 46305 | O23: =IF(M23="",0,(N23-M23)+1) -> 248 | P23: =O23/30 -> 8.2666667 | Q23: =VLOOKUP($G23,Agendamento!$B:$F,5,0) -> 5 | R23: =IF(U23="",0,ROUNDUP($I23/1000,0)) -> 37 | S23: 2.55 | T23: =O23*R23*S23 -> 23398.8 | U23: 64237227_20260205_nf_07.pdf | V23: =CONCATENATE("NF/",U23) -> NF/64237227_20260205_nf_07.pdf | W23: =HYPERLINK(CONCATENATE("saida/",U23),CONCATENATE("NF - ",G23)) -> NF - INÁCIO! LARGA ESSE CELULAR | X23: CORRIGIDO
A24: =CONCATENATE(D24,"_",TEXT(M24,"ddmmaaaa"),"_",COUNTIF($D$2:D24,D24)) -> 720440500001-81_06022026_1 | B24: =CONCATENATE(Analise!D24,"_",COUNTIF(Analise!$D$2:D24,Analise!D24)) -> 720440500001-81_1 | C24: =COUNTIF('Obras e Acervos'!$C:$C,CONCATENATE(LEFT(D24,12),RIGHT(D24,2))) -> 1 | D24: 720440500001-81 | E24: =VLOOKUP($B24,'Obras e Acervos'!$B:$X,3,0) -> IMO S GRAFICA E EDITORA LTDA- | F24: =VLOOKUP($B24,'Obras e Acervos'!$B:$X,7,0) -> 1129L23000030LE | G24: =VLOOKUP($B24,'Obras e Acervos'!$B:$X,5,0) -> DORA, UMA MENINA NORDESTINA | H24: =VLOOKUP($B24,'Obras e Acervos'!$B:$X,18,0) -> 9 | I24: =VLOOKUP($B24,'Obras e Acervos'!$B:$X,19,0) -> 37900 | J24: =VLOOKUP($B24,'Obras e Acervos'!$B:$X,20,0) -> 3979.5 | K24: =VLOOKUP($B24,'Obras e Acervos'!$B:$X,21,0) -> 5.49 | L24: =K24*I24 -> 208071 | M24: 46059 | N24: =$AB$2 -> 46305 | O24: =IF(M24="",0,(N24-M24)+1) -> 247 | P24: =O24/30 -> 8.2333333 | Q24: =VLOOKUP($G24,Agendamento!$B:$F,5,0) -> 5 | R24: =IF(U24="",0,ROUNDUP($I24/1000,0)) -> 38 | S24: 2.55 | T24: =O24*R24*S24 -> 23934.3 | U24: 64237413_20260206_nf_01.pdf | V24: =CONCATENATE("NF/",U24) -> NF/64237413_20260206_nf_01.pdf | W24: =HYPERLINK(CONCATENATE("saida/",U24),CONCATENATE("NF - ",G24)) -> NF - DORA, UMA MENINA NORDESTINA | X24: OK
A25: =CONCATENATE(D25,"_",TEXT(M25,"ddmmaaaa"),"_",COUNTIF($D$2:D25,D25)) -> 171726860001-09_06022026_1 | B25: =CONCATENATE(Analise!D25,"_",COUNTIF(Analise!$D$2:D25,Analise!D25)) -> 171726860001-09_1 | C25: =COUNTIF('Obras e Acervos'!$C:$C,CONCATENATE(LEFT(D25,12),RIGHT(D25,2))) -> 2 | D25: 171726860001-09 | E25: =VLOOKUP($B25,'Obras e Acervos'!$B:$X,3,0) -> VMP REPRESENTACOES E COMERCIO LTDA-VMP REPRESENTACOES E COMERCIO | F25: =VLOOKUP($B25,'Obras e Acervos'!$B:$X,7,0) -> 0664L23000030LE | G25: =VLOOKUP($B25,'Obras e Acervos'!$B:$X,5,0) -> MARIA FLOR | H25: =VLOOKUP($B25,'Obras e Acervos'!$B:$X,18,0) -> 5 | I25: =VLOOKUP($B25,'Obras e Acervos'!$B:$X,19,0) -> 37726 | J25: =VLOOKUP($B25,'Obras e Acervos'!$B:$X,20,0) -> 4338.49 | K25: =VLOOKUP($B25,'Obras e Acervos'!$B:$X,21,0) -> 5.91 | L25: =K25*I25 -> 222960.66 | M25: 46059 | N25: =$AB$2 -> 46305 | O25: =IF(M25="",0,(N25-M25)+1) -> 247 | P25: =O25/30 -> 8.2333333 | Q25: =VLOOKUP($G25,Agendamento!$B:$F,5,0) -> 5 | R25: =IF(U25="",0,ROUNDUP($I25/1000,0)) -> 38 | S25: 2.55 | T25: =O25*R25*S25 -> 23934.3 | U25: 64237413_20260206_nf_02.pdf | V25: =CONCATENATE("NF/",U25) -> NF/64237413_20260206_nf_02.pdf | W25: =HYPERLINK(CONCATENATE("saida/",U25),CONCATENATE("NF - ",G25)) -> NF - MARIA FLOR | X25: OK
A26: =CONCATENATE(D26,"_",TEXT(M26,"ddmmaaaa"),"_",COUNTIF($D$2:D26,D26)) -> 171726860001-09_06022026_2 | B26: =CONCATENATE(Analise!D26,"_",COUNTIF(Analise!$D$2:D26,Analise!D26)) -> 171726860001-09_2 | C26: =COUNTIF('Obras e Acervos'!$C:$C,CONCATENATE(LEFT(D26,12),RIGHT(D26,2))) -> 2 | D26: 171726860001-09 | E26: =VLOOKUP($B26,'Obras e Acervos'!$B:$X,3,0) -> VMP REPRESENTACOES E COMERCIO LTDA-VMP REPRESENTACOES E COMERCIO | F26: =VLOOKUP($B26,'Obras e Acervos'!$B:$X,7,0) -> 0667L23000020LE | G26: =VLOOKUP($B26,'Obras e Acervos'!$B:$X,5,0) -> O OLHO DA RUA | H26: =VLOOKUP($B26,'Obras e Acervos'!$B:$X,18,0) -> 22 | I26: =VLOOKUP($B26,'Obras e Acervos'!$B:$X,19,0) -> 23919 | J26: =VLOOKUP($B26,'Obras e Acervos'!$B:$X,20,0) -> 3659.607 | K26: =VLOOKUP($B26,'Obras e Acervos'!$B:$X,21,0) -> 8.92 | L26: =K26*I26 -> 213357.48 | M26: 46059 | N26: =$AB$2 -> 46305 | O26: =IF(M26="",0,(N26-M26)+1) -> 247 | P26: =O26/30 -> 8.2333333 | Q26: =VLOOKUP($G26,Agendamento!$B:$F,5,0) -> 4 | R26: =IF(U26="",0,ROUNDUP($I26/1000,0)) -> 24 | S26: 2.55 | T26: =O26*R26*S26 -> 15116.4 | U26: 64237413_20260206_nf_02.pdf | V26: =CONCATENATE("NF/",U26) -> NF/64237413_20260206_nf_02.pdf | W26: =HYPERLINK(CONCATENATE("saida/",U26),CONCATENATE("NF - ",G26)) -> NF - O OLHO DA RUA | X26: OK
A27: =CONCATENATE(D27,"_",TEXT(M27,"ddmmaaaa"),"_",COUNTIF($D$2:D27,D27)) -> 407961540001-56_06022026_1 | B27: =CONCATENATE(Analise!D27,"_",COUNTIF(Analise!$D$2:D27,Analise!D27)) -> 407961540001-56_1 | C27: =COUNTIF('Obras e Acervos'!$C:$C,CONCATENATE(LEFT(D27,12),RIGHT(D27,2))) -> 1 | D27: 407961540001-56 | E27: =VLOOKUP($B27,'Obras e Acervos'!$B:$X,3,0) -> ARTHUR SILVEIRA EDITORA LTDA-CURIOSAMENTE EDITORA | F27: =VLOOKUP($B27,'Obras e Acervos'!$B:$X,7,0) -> 0585L23000020LE | G27: =VLOOKUP($B27,'Obras e Acervos'!$B:$X,5,0) -> DO MAR | H27: =VLOOKUP($B27,'Obras e Acervos'!$B:$X,18,0) -> 19 | I27: =VLOOKUP($B27,'Obras e Acervos'!$B:$X,19,0) -> 26467 | J27: =VLOOKUP($B27,'Obras e Acervos'!$B:$X,20,0) -> 4287.654 | K27: =VLOOKUP($B27,'Obras e Acervos'!$B:$X,21,0) -> 9.26 | L27: =K27*I27 -> 245084.42 | M27: 46059 | N27: =$AB$2 -> 46305 | O27: =IF(M27="",0,(N27-M27)+1) -> 247 | P27: =O27/30 -> 8.2333333 | Q27: =VLOOKUP($G27,Agendamento!$B:$F,5,0) -> 5 | R27: =IF(U27="",0,ROUNDUP($I27/1000,0)) -> 27 | S27: 2.55 | T27: =O27*R27*S27 -> 17005.95 | U27: 64237413_20260206_nf_03.pdf | V27: =CONCATENATE("NF/",U27) -> NF/64237413_20260206_nf_03.pdf | W27: =HYPERLINK(CONCATENATE("saida/",U27),CONCATENATE("NF - ",G27)) -> NF - DO MAR | X27: OK
A28: =CONCATENATE(D28,"_",TEXT(M28,"ddmmaaaa"),"_",COUNTIF($D$2:D28,D28)) -> 249805720001-42_06022026_1 | B28: =CONCATENATE(Analise!D28,"_",COUNTIF(Analise!$D$2:D28,Analise!D28)) -> 249805720001-42_1 | C28: =COUNTIF('Obras e Acervos'!$C:$C,CONCATENATE(LEFT(D28,12),RIGHT(D28,2))) -> 1 | D28: 249805720001-42 | E28: =VLOOKUP($B28,'Obras e Acervos'!$B:$X,3,0) -> A A MENEGHETTI SOLUCOES EM ENGENHARIA-MENEGHETTI SOLUCOES EM ENGENHARIA | F28: =VLOOKUP($B28,'Obras e Acervos'!$B:$X,7,0) -> 0598L23000030LE | G28: =VLOOKUP($B28,'Obras e Acervos'!$B:$X,5,0) -> MEU ZÉ LELÉ DE ESTIMAÇÃO | H28: =VLOOKUP($B28,'Obras e Acervos'!$B:$X,18,0) -> 2 | I28: =VLOOKUP($B28,'Obras e Acervos'!$B:$X,19,0) -> 43589 | J28: =VLOOKUP($B28,'Obras e Acervos'!$B:$X,20,0) -> 5405.036 | K28: =VLOOKUP($B28,'Obras e Acervos'!$B:$X,21,0) -> 5.87 | L28: =K28*I28 -> 255867.43 | M28: 46059 | N28: =$AB$2 -> 46305 | O28: =IF(M28="",0,(N28-M28)+1) -> 247 | P28: =O28/30 -> 8.2333333 | Q28: =VLOOKUP($G28,Agendamento!$B:$F,5,0) -> 6 | R28: =IF(U28="",0,ROUNDUP($I28/1000,0)) -> 44 | S28: 2.55 | T28: =O28*R28*S28 -> 27713.4 | U28: 64237413_20260206_nf_04.pdf | V28: =CONCATENATE("NF/",U28) -> NF/64237413_20260206_nf_04.pdf | W28: =HYPERLINK(CONCATENATE("saida/",U28),CONCATENATE("NF - ",G28)) -> NF - MEU ZÉ LELÉ DE ESTIMAÇÃO | X28: OK
A29: =CONCATENATE(D29,"_",TEXT(M29,"ddmmaaaa"),"_",COUNTIF($D$2:D29,D29)) -> 070529780001-46_06022026_1 | B29: =CONCATENATE(Analise!D29,"_",COUNTIF(Analise!$D$2:D29,Analise!D29)) -> 070529780001-46_1 | C29: =COUNTIF('Obras e Acervos'!$C:$C,CONCATENATE(LEFT(D29,12),RIGHT(D29,2))) -> 2 | D29: 070529780001-46 | E29: =VLOOKUP($B29,'Obras e Acervos'!$B:$X,3,0) -> ELEMENTAR PUBLICAÇÕES E EDITORA LTDA-ELEMENTAR PUBLICAÇÕES | F29: =VLOOKUP($B29,'Obras e Acervos'!$B:$X,7,0) -> 0844L23000030LE | G29: =VLOOKUP($B29,'Obras e Acervos'!$B:$X,5,0) -> VOVÓ CRISÁLIDA E O MISTÉRIO DA CAIXA DE FOTOGRAFIAS | H29: =VLOOKUP($B29,'Obras e Acervos'!$B:$X,18,0) -> 9 | I29: =VLOOKUP($B29,'Obras e Acervos'!$B:$X,19,0) -> 34249 | J29: =VLOOKUP($B29,'Obras e Acervos'!$B:$X,20,0) -> 3596.145 | K29: =VLOOKUP($B29,'Obras e Acervos'!$B:$X,21,0) -> 5.91 | L29: =K29*I29 -> 202411.59 | M29: 46059 | N29: =$AB$2 -> 46305 | O29: =IF(M29="",0,(N29-M29)+1) -> 247 | P29: =O29/30 -> 8.2333333 | Q29: =VLOOKUP($G29,Agendamento!$B:$F,5,0) -> 4 | R29: =IF(U29="",0,ROUNDUP($I29/1000,0)) -> 35 | S29: 2.55 | T29: =O29*R29*S29 -> 22044.75 | U29: 64237413_20260206_nf_05.pdf | V29: =CONCATENATE("NF/",U29) -> NF/64237413_20260206_nf_05.pdf | W29: =HYPERLINK(CONCATENATE("saida/",U29),CONCATENATE("NF - ",G29)) -> NF - VOVÓ CRISÁLIDA E O MISTÉRIO DA CAIXA DE FOTOGRAFIAS | X29: OK
A30: =CONCATENATE(D30,"_",TEXT(M30,"ddmmaaaa"),"_",COUNTIF($D$2:D30,D30)) -> 444618360001-69_06022026_1 | B30: =CONCATENATE(Analise!D30,"_",COUNTIF(Analise!$D$2:D30,Analise!D30)+1) -> 444618360001-69_2 | C30: =COUNTIF('Obras e Acervos'!$C:$C,CONCATENATE(LEFT(D30,12),RIGHT(D30,2))) -> 2 | D30: 444618360001-69 | E30: =VLOOKUP($B30,'Obras e Acervos'!$B:$X,3,0) -> EDITORA YELLOWFANTE LTDA-INVENTADEIRA | F30: =VLOOKUP($B30,'Obras e Acervos'!$B:$X,7,0) -> 0725L23000020LE | G30: =VLOOKUP($B30,'Obras e Acervos'!$B:$X,5,0) -> PARAÓ E PEBA | H30: =VLOOKUP($B30,'Obras e Acervos'!$B:$X,18,0) -> 18 | I30: =VLOOKUP($B30,'Obras e Acervos'!$B:$X,19,0) -> 23988 | J30: =VLOOKUP($B30,'Obras e Acervos'!$B:$X,20,0) -> 2518.74 | K30: =VLOOKUP($B30,'Obras e Acervos'!$B:$X,21,0) -> 6.57 | L30: =K30*I30 -> 157601.16 | M30: 46059 | N30: =$AB$2 -> 46305 | O30: =IF(M30="",0,(N30-M30)+1) -> 247 | P30: =O30/30 -> 8.2333333 | Q30: =VLOOKUP($G30,Agendamento!$B:$F,5,0) -> 3 | R30: =IF(U30="",0,ROUNDUP($I30/1000,0)) -> 24 | S30: 2.55 | T30: =O30*R30*S30 -> 15116.4 | U30: 64237413_20260206_nf_06.pdf | V30: =CONCATENATE("NF/",U30) -> NF/64237413_20260206_nf_06.pdf | W30: =HYPERLINK(CONCATENATE("saida/",U30),CONCATENATE("NF - ",G30)) -> NF - PARAÓ E PEBA | X30: OK
A31: =CONCATENATE(D31,"_",TEXT(M31,"ddmmaaaa"),"_",COUNTIF($D$2:D31,D31)) -> 433990010001-63_06022026_1 | B31: =CONCATENATE(Analise!D31,"_",COUNTIF(Analise!$D$2:D31,Analise!D31)+1) -> 433990010001-63_2 | C31: =COUNTIF('Obras e Acervos'!$C:$C,CONCATENATE(LEFT(D31,12),RIGHT(D31,2))) -> 2 | D31: 433990010001-63 | E31: =VLOOKUP($B31,'Obras e Acervos'!$B:$X,3,0) -> MARTHA EDITORA LTDA-MARTHA EDITORA | F31: =VLOOKUP($B31,'Obras e Acervos'!$B:$X,7,0) -> 0482L23000020LE | G31: =VLOOKUP($B31,'Obras e Acervos'!$B:$X,5,0) -> O PASTOR E A BORDADEIRA | H31: =VLOOKUP($B31,'Obras e Acervos'!$B:$X,18,0) -> 18 | I31: =VLOOKUP($B31,'Obras e Acervos'!$B:$X,19,0) -> 23533 | J31: =VLOOKUP($B31,'Obras e Acervos'!$B:$X,20,0) -> 2470.965 | K31: =VLOOKUP($B31,'Obras e Acervos'!$B:$X,21,0) -> 6.6 | L31: =K31*I31 -> 155317.8 | M31: 46059 | N31: =$AB$2 -> 46305 | O31: =IF(M31="",0,(N31-M31)+1) -> 247 | P31: =O31/30 -> 8.2333333 | Q31: =VLOOKUP($G31,Agendamento!$B:$F,5,0) -> 3 | R31: =IF(U31="",0,ROUNDUP($I31/1000,0)) -> 24 | S31: 2.55 | T31: =O31*R31*S31 -> 15116.4 | U31: 64237413_20260206_nf_07.pdf | V31: =CONCATENATE("NF/",U31) -> NF/64237413_20260206_nf_07.pdf | W31: =HYPERLINK(CONCATENATE("saida/",U31),CONCATENATE("NF - ",G31)) -> NF - O PASTOR E A BORDADEIRA | X31: OK
A32: =CONCATENATE(D32,"_",TEXT(M32,"ddmmaaaa"),"_",COUNTIF($D$2:D32,D32)) -> 334617510001-64_06022026_1 | B32: =CONCATENATE(Analise!D32,"_",COUNTIF(Analise!$D$2:D32,Analise!D32)+1) -> 334617510001-64_2 | C32: =COUNTIF('Obras e Acervos'!$C:$C,CONCATENATE(LEFT(D32,12),RIGHT(D32,2))) -> 2 | D32: 334617510001-64 | E32: =VLOOKUP($B32,'Obras e Acervos'!$B:$X,3,0) -> D. PADILHA ESTÚDIO EDITORIAL-LITERATURA DE COLO EDITORA | F32: =VLOOKUP($B32,'Obras e Acervos'!$B:$X,7,0) -> 0581L23000020LE | G32: =VLOOKUP($B32,'Obras e Acervos'!$B:$X,5,0) -> O PÁSSARO ENCANTADO | H32: =VLOOKUP($B32,'Obras e Acervos'!$B:$X,18,0) -> 22 | I32: =VLOOKUP($B32,'Obras e Acervos'!$B:$X,19,0) -> 26828 | J32: =VLOOKUP($B32,'Obras e Acervos'!$B:$X,20,0) -> 2682.8 | K32: =VLOOKUP($B32,'Obras e Acervos'!$B:$X,21,0) -> 6.41 | L32: =K32*I32 -> 171967.48 | M32: 46059 | N32: =$AB$2 -> 46305 | O32: =IF(M32="",0,(N32-M32)+1) -> 247 | P32: =O32/30 -> 8.2333333 | Q32: =VLOOKUP($G32,Agendamento!$B:$F,5,0) -> 3 | R32: =IF(U32="",0,ROUNDUP($I32/1000,0)) -> 27 | S32: 2.55 | T32: =O32*R32*S32 -> 17005.95 | U32: 64237413_20260206_nf_08.pdf | V32: =CONCATENATE("NF/",U32) -> NF/64237413_20260206_nf_08.pdf | W32: =HYPERLINK(CONCATENATE("saida/",U32),CONCATENATE("NF - ",G32)) -> NF - O PÁSSARO ENCANTADO | X32: OK
